Workbook

Sheet Sheet1
B1: place_id | C1: author | D1: join_col | E1: rating | F1: date | G1: text | H1: place_name | I1: index | J1: date_parsed | K1: ABSA_manual | L1: atepc_json | M1: flag | N1: len_manual | O1: len_atepc | P1: len_g1 | Q1: len_g2 | R1: len_g3 | S1: len_g4 | T1: diff_g1 | U1: diff_g2 | V1: diff_g3 | W1: diff_g4 | X1: xgn | AH1: gj
A2: 255 | B2: ChIJ3SGSkBkFkWsR6tKcdeWSRZA | C2: Chloe Ramsdale | D2: ChIJ3SGSkBkFkWsR6tKcdeWSRZAChloe Ramsdale | E2: 1 | F2: a year ago | G2: Waste of money. Room is tiny and filled with plastic ice, random decor and a few games to try entertain... Felt very awkward and rushed. Not allowed to take your own photos and half of the cameras in there were broken, which was just met … | H2: IceBar Surfers | I2: 15776 | J2: 2024-10-10 | K2: {"overall_sentiment":"negative","aspects":[{"aspect":"room","category":"space","sentiment":"negative","evidence_span":"Room is tiny"},{"aspect":"decor","category":"ambience","sentiment":"negative","evidence_span":"random decor"},{"aspect":"photo policy","category":"policy","sentiment":"negative","evidence_span":"Not allowed"},{"aspect":"cameras","category":"equipment","sentiment":"negative","evidence_span":"were broken"}, {'aspect': 'games',"category":"entertainment", 'opinion': 'few', 'sentiment': 'negative'}, {'aspect': 'value for money',"category":"price", 'opinion': 'waste of money', 'sentiment': 'negative'}, {'aspect': 'experience',"category":"experience", 'opinion': 'awkward', 'sentiment': 'negative'}]} | L2: {'sentence': 'Waste of money . Room is tiny and filled with plastic ice , random decor and a few games to try entertain . . . Felt very awkward and rushed . Not allowed to take your own photos and half of the cameras in there were broken , which was just met …', 'IOB': ['O', 'O', 'O', 'O', 'O', 'O', 'O', 'O', 'O', 'O', 'O', 'O', 'O', 'O', 'B-ASP', 'O', 'O', 'O', 'B-ASP', 'O', 'O', 'O', 'O', 'O', 'O', 'O', 'O', 'O', 'O', 'O', 'O', 'O', 'O', 'O', 'O', 'O', 'O', 'O', 'O', 'O', 'O', 'O', 'O', 'O', 'O', 'O', 'O', 'O', 'O', 'O', 'O', 'O', 'O'], 'tokens': ['Waste', 'of', 'money', '.', 'Room', 'is', 'tiny', 'and', 'filled', 'with', 'plastic', 'ice', ',', 'random', 'decor', 'and', 'a', 'few', 'games', 'to', 'try', 'entertain', '.', '.', '.', 'Felt', 'very', 'awkward', 'and', 'rushed', '.', 'Not', 'allowed', 'to', 'take', 'your', 'own', 'photos', 'and', 'half', 'of', 'the', 'cameras', 'in', 'there', 'were', 'broken', ',', 'which', 'was', 'just', 'met', '…'], 'aspect': ['decor', 'games'], 'position': [[14], [18]], 'sentiment': ['Negative', 'Negative'], 'probs': [[0.971028208732605, 0.028118714690208435, 0.0008530318737030029], [0.6798680424690247, 0.31912750005722046, 0.0010044979862868786]], 'confidence': [0.971, 0.6799]} | M2: 1 | N2: =LEN(K2)-LEN(SUBSTITUTE(K2,"{",""))-1 -> 7 | O2: 2 | P2: =_xlfn.XLOOKUP(B2,'g1'!B:B,'g1'!R:R) -> 8 | Q2: =_xlfn.XLOOKUP(B2,'g2'!B:B,'g2'!U:U) -> 7 | R2: =_xlfn.XLOOKUP(B2,'g3'!B:B,'g3'!R:R) -> 6 | S2: =_xlfn.XLOOKUP(D2,'g4'!D:D,'g4'!N:N) -> 8 | T2: =$N2-P2 -> -1 | U2: =$N2-Q2 -> 0 | V2: =$N2-R2 -> 1 | W2: =$N2-S2 -> -1 | X2: [{'aspect': 'room', 'opinion': 'tiny', 'sentiment': 'negative'}, {'aspect': 'ice', 'opinion': 'plastic', 'sentiment': 'negative'}, {'aspect': 'decor', 'opinion': 'random', 'sentiment': 'negative'}, {'aspect': 'games', 'opinion': 'few', 'sentiment': 'negative'}, {'aspect': 'photo policy', 'opinion': 'not allowed to take your own photos', 'sentiment': 'negative'}, {'aspect': 'cameras', 'opinion': 'half of the cameras in there were broken', 'sentiment': 'negative'}, {'aspect': 'value for money', 'opinion': 'waste of money', 'sentiment': 'negative'}, {'aspect': 'experience', 'opinion': 'awkward', 'sentiment': 'negative'}] | Y2: =FIND("[{",K2) -> 43 | Z2: =FIND("category",K2) -> 62 | AA2: =Z2-Y2-2 -> 17 | AB2: room | AD2: =FIND("[{",X2) -> 1 | AE2: =FIND("opinion",X2) -> 22 | AF2: =AE2-AD2-2 -> 19 | AG2: room | AH2: =AB2=AG2 -> TRUE
A3: 1480 | B3: ChIJoWNwIKNQkWsRoLkh11ujAg8 | C3: Colin wick | D3: ChIJoWNwIKNQkWsRoLkh11ujAg8Colin wick | E3: 4 | F3: a year ago | G3: Great spirit from both visitors and stall holders - very vibrant yet peaceful environment. I purchased fresh flowers, fruit & veg and bakery products. Coffee and fresh juice was very good. Prices were generally good with fresh products … | H3: The West End Markets | I3: 434 | J3: 2024-10-10 | K3: {"overall_sentiment":"positive","aspects":[{"aspect":"spirit","category":"atmosphere","sentiment":"positive","evidence_span":"Great spirit"},{"aspect":"environment","category":"atmosphere","sentiment":"positive","evidence_span":"peaceful environment"},{"aspect":"coffee","category":"beverage","sentiment":"positive","evidence_span":"very good"},{"aspect":"fresh juice","category":"beverage","sentiment":"positive","evidence_span":"very good"},{"aspect":"prices","category":"pricing","sentiment":"positive","evidence_span":"generally good"}]} | L3: {'sentence': 'Great spirit from both visitors and stall holders - very vibrant yet peaceful environment . I purchased fresh flowers , fruit & veg and bakery products . Coffee and fresh juice was very good . Prices were generally good with fresh products …', 'IOB': ['O', 'O', 'O', 'O', 'O', 'O', 'B-ASP', 'I-ASP', 'O', 'O', 'O', 'O', 'O', 'B-ASP', 'O', 'O', 'O', 'O', 'O', 'O', 'O', 'O', 'O', 'O', 'O', 'O', 'O', 'B-ASP', 'O', 'O', 'B-ASP', 'O', 'O', 'O', 'O', 'B-ASP', 'O', 'O', 'O', 'O', 'O', 'O', 'O'], 'tokens': ['Great', 'spirit', 'from', 'both', 'visitors', 'and', 'stall', 'holders', '-', 'very', 'vibrant', 'yet', 'peaceful', 'environment', '.', 'I', 'purchased', 'fresh', 'flowers', ',', 'fruit', '&', 'veg', 'and', 'bakery', 'products', '.', 'Coffee', 'and', 'fresh', 'juice', 'was', 'very', 'good', '.', 'Prices', 'were', 'generally', 'good', 'with', 'fresh', 'products', '…'], 'aspect': ['stall holders', 'environment', 'Coffee', 'juice', 'Prices'], 'position': [[6, 7], [13], [27], [30], [35]], 'sentiment': ['Positive', 'Positive', 'Positive', 'Positive', 'Positive'], 'probs': [[0.0002124903112417087, 0.000311657931888476, 0.99947589635849], [0.00018766136781778187, 0.0004186705918982625, 0.9993937015533447], [0.0002741042117122561, 0.0005672599072568119, 0.9991586208343506], [0.0002939401601906866, 0.000521963054779917, 0.9991840720176697], [0.0002796389744617045, 0.0004245512536726892, 0.9992958307266235]], 'confidence': [0.9995, 0.9994, 0.9992, 0.9992, 0.9993]} | N3: =LEN(K3)-LEN(SUBSTITUTE(K3,"{",""))-1 -> 5 | O3: 5 | P3: =_xlfn.XLOOKUP(B3,'g1'!B:B,'g1'!R:R) -> 9 | Q3: =_xlfn.XLOOKUP(B3,'g2'!B:B,'g2'!U:U) -> 9 | R3: =_xlfn.XLOOKUP(B3,'g3'!B:B,'g3'!R:R) -> 5 | S3: =_xlfn.XLOOKUP(D3,'g4'!D:D,'g4'!N:N) -> 7 | T3: =$N3-P3 -> -4 | U3: =$N3-Q3 -> -4 | V3: =$N3-R3 -> 0 | W3: =$N3-S3 -> -2 | X3: [{'aspect': 'fresh flowers', 'opinion': 'fresh', 'sentiment': 'neutral'}, {'aspect': 'fruit & veg', 'opinion': 'fresh', 'sentiment': 'neutral'}, {'aspect': 'bakery products', 'opinion': 'fresh', 'sentiment': 'neutral'}, {'aspect': 'coffee', 'opinion': 'very good', 'sentiment': 'positive'}, {'aspect': 'fresh juice', 'opinion': 'very good', 'sentiment': 'positive'}, {'aspect': 'environment', 'opinion': 'very vibrant', 'sentiment': 'positive'}, {'aspect': 'prices', 'opinion': 'good', 'sentiment': 'positive'}] | Y3: =FIND("[{",K3) -> 43 | Z3: =FIND("category",K3) -> 64 | AA3: =Z3-Y3-2 -> 19 | AB3: spirit | AD3: =FIND("[{",X3) -> 1 | AE3: =FIND("opinion",X3) -> 31 | AF3: =AE3-AD3-2 -> 28 | AG3: fresh flowers | AH3: =AB3=AG3 -> FALSE
A4: 1504 | B4: ChIJP7OFsOzvkGsRcMf9c7UJBg8 | C4: Jack Hamers | D4: ChIJP7OFsOzvkGsRcMf9c7UJBg8Jack Hamers | E4: 2 | F4: 7 years ago | G4: Bar service was excellent. Food service was great but the food really let's down the club. Expensive and it is either deep fried fast food or flavorless a really disappointment for the club. Awesome Raffles! | H4: Murwillumbah Golf Club | I4: 7671 | J4: 2018-10-12 | K4: {"overall_sentiment":"negative","aspects":[{"aspect":"bar service","category":"service","sentiment":"positive","evidence_span":"was excellent"},{"aspect":"food service","category":"service","sentiment":"positive","evidence_span":"was great"},{"aspect":"food","category":"food","sentiment":"negative","evidence_span":"let's down"},{"aspect":"price","category":"price","sentiment":"negative","evidence_span":"Expensive"},{"aspect":"Raffles","category":"entertainment","sentiment":"positive","evidence_span":"Awesome Raffles!"}]} | L4: {'sentence': "Bar service was excellent . Food service was great but the food really let ' s down the club . Expensive and it is either deep fried fast food or flavorless a really disappointment for the club . Awesome Raffles !", 'IOB': ['B-ASP', 'I-ASP', 'O', 'O', 'O', 'B-ASP', 'I-ASP', 'O', 'O', 'O', 'O', 'B-ASP', 'O', 'O', 'O', 'O', 'O', 'O', 'O', 'O', 'O', 'O', 'O', 'O', 'O', 'O', 'O', 'O', 'O', 'O', 'O', 'O', 'O', 'O', 'O', 'O', 'O', 'O', 'O', 'O', 'O'], 'tokens': ['Bar', 'service', 'was', 'excellent', '.', 'Food', 'service', 'was', 'great', 'but', 'the', 'food', 'really', 'let', "'", 's', 'down', 'the', 'club', '.', 'Expensive', 'and', 'it', 'is', 'either', 'deep', 'fried', 'fast', 'food', 'or', 'flavorless', 'a', 'really', 'disappointment', 'for', 'the', 'club', '.', 'Awesome', 'Raffles', '!'], 'aspect': ['Bar service', 'Food service', 'food'], 'position': [[0, 1], [5, 6], [11]], 'sentiment': ['Positive', 'Positive', 'Negative'], 'probs': [[0.015679549425840378, 0.0008737363386899233, 0.9834467768669128], [0.02416217513382435, 0.0008892863988876343, 0.974948525428772], [0.8960981965065002, 0.014301101677119732, 0.08960071206092834]], 'confidence': [0.9834, 0.9749, 0.8961]} | M4: 1 | N4: =LEN(K4)-LEN(SUBSTITUTE(K4,"{",""))-1 -> 5 | O4: 3 | P4: =_xlfn.XLOOKUP(B4,'g1'!B:B,'g1'!R:R) -> 5 | Q4: =_xlfn.XLOOKUP(B4,'g2'!B:B,'g2'!U:U) -> 5 | R4: =_xlfn.XLOOKUP(B4,'g3'!B:B,'g3'!R:R) -> 4 | S4: =_xlfn.XLOOKUP(D4,'g4'!D:D,'g4'!N:N) -> 7 | T4: =$N4-P4 -> 0 | U4: =$N4-Q4 -> 0 | V4: =$N4-R4 -> 1 | W4: =$N4-S4 -> -2 | X4: [{'aspect': 'bar service', 'opinion': 'excellent', 'sentiment': 'positive'}, {'aspect': 'food service', 'opinion': 'great', 'sentiment': 'positive'}, {'aspect': 'food', 'opinion': 'let down', 'sentiment': 'negative'}, {'aspect': 'food', 'opinion': 'expensive', 'sentiment': 'negative'}, {'aspect': 'food', 'opinion': 'flavorless', 'sentiment': 'negative'}, {'aspect': 'food', 'opinion': 'disappointment', 'sentiment': 'negative'}, {'aspect': 'raffles', 'opinion': 'awesome', 'sentiment': 'positive'}] | Y4: =FIND("[{",K4) -> 43 | Z4: =FIND("category",K4) -> 69 | AA4: =Z4-Y4-2 -> 24 | AB4: bar service | AD4: =FIND("[{",X4) -> 1 | AE4: =FIND("opinion",X4) -> 29 | AF4: =AE4-AD4-2 -> 26 | AG4: bar service | AH4: =AB4=AG4 -> TRUE
A5: 1087 | B5: ChIJaezMtIGAvmsRbLcaWOBK59o | C5: mark brinkhuizen | D5: ChIJaezMtIGAvmsRbLcaWOBK59omark brinkhuizen | E5: 3 | F5: 10 months ago | G5: Stayed here 2 nights. Excellent flush toilets. There is no power or water but plenty of space and level sites. There is a creek you can swim in. We enjoyed our stay | H5: Chinchilla Weir Camping | I5: 7914 | J5: 2024-12-14 | K5: {"overall_sentiment":"positive","aspects":[{"aspect":"flush toilets","category":"facilities","sentiment":"positive","evidence_span":"Excellent flush toilets"},{"aspect":"power","category":"utilities","sentiment":"negative","evidence_span":"no power"},{"aspect":"water","category":"utilities","sentiment":"negative","evidence_span":"no water"},{"aspect":"space","category":"space","sentiment":"positive","evidence_span":"plenty of space"},{"aspect":"sites","category":"site","sentiment":"positive","evidence_span":"level sites"}, {'aspect': 'creek',"category":"creek", 'opinion': 'can swim in', 'sentiment': 'positive'}]} | L5: {'sentence': 'Stayed here 2 nights . Excellent flush toilets . There is no power or water but plenty of space and level sites . There is a creek you can swim in . We enjoyed our stay', 'IOB': ['O', 'O', 'O', 'O', 'O', 'O', 'O', 'B-ASP', 'O', 'O', 'O', 'O', 'O', 'O', 'O', 'O', 'O', 'O', 'O', 'O', 'O', 'O', 'O', 'O', 'O', 'O', 'O', 'O', 'O', 'O', 'O', 'O', 'O', 'O', 'O', 'O'], 'tokens': ['Stayed', 'here', '2', 'nights', '.', 'Excellent', 'flush', 'toilets', '.', 'There', 'is', 'no', 'power', 'or', 'water', 'but', 'plenty', 'of', 'space', 'and', 'level', 'sites', '.', 'There', 'is', 'a', 'creek', 'you', 'can', 'swim', 'in', '.', 'We', 'enjoyed', 'our', 'stay'], 'aspect': ['toilets'], 'position': [[7]], 'sentiment': ['Positive'], 'probs': [[0.0007605825085192919, 0.0005012063775211573, 0.9987382292747498]], 'confidence': [0.9987]} | M5: 1 | N5: =LEN(K5)-LEN(SUBSTITUTE(K5,"{",""))-1 -> 6 | O5: 1 | P5: =_xlfn.XLOOKUP(B5,'g1'!B:B,'g1'!R:R) -> 7 | Q5: =_xlfn.XLOOKUP(B5,'g2'!B:B,'g2'!U:U) -> 7 | R5: =_xlfn.XLOOKUP(B5,'g3'!B:B,'g3'!R:R) -> 6 | S5: =_xlfn.XLOOKUP(D5,'g4'!D:D,'g4'!N:N) -> 7 | T5: =$N5-P5 -> -1 | U5: =$N5-Q5 -> -1 | V5: =$N5-R5 -> 0 | W5: =$N5-S5 -> -1 | X5: [{'aspect': 'flush toilets', 'opinion': 'Excellent', 'sentiment': 'positive'}, {'aspect': 'sites', 'opinion': 'level', 'sentiment': 'positive'}, {'aspect': 'power', 'opinion': 'no', 'sentiment': 'negative'}, {'aspect': 'water', 'opinion': 'no', 'sentiment': 'negative'}, {'aspect': 'space', 'opinion': 'plenty', 'sentiment': 'positive'}, {'aspect': 'creek', 'opinion': 'can swim in', 'sentiment': 'positive'}, {'aspect': 'stay', 'opinion': 'enjoyed', 'sentiment': 'positive'}] | Y5: =FIND("[{",K5) -> 43 | Z5: =FIND("category",K5) -> 71 | AA5: =Z5-Y5-2 -> 26 | AB5: toilets | AD5: =FIND("[{",X5) -> 1 | AE5: =FIND("opinion",X5) -> 31 | AF5: =AE5-AD5-2 -> 28 | AG5: flush toilets | AH5: =AB5=AG5 -> FALSE
A6: 943 | B6: ChIJpRd2-64P1moRNjJXWrrA53k | C6: Darren Lawson | D6: ChIJpRd2-64P1moRNjJXWrrA53kDarren Lawson | E6: 4 | F6: a year ago | G6: Nice atmosphere, lots of different types of entertainment from sports betting, horse racing, greyhound racing, pokies, bingo and more. … | H6: Trios Sports Club | I6: 2800 | J6: 2024-10-10 | K6: {"overall_sentiment":"positive","aspects":[{"aspect":"atmosphere","category":"ambience","sentiment":"positive","evidence_span":"Nice atmosphere"},{'aspect': 'sports betting', 'opinion': 'lots of different types of entertainment', 'sentiment': 'positive'}, {'aspect': 'horse racing', 'opinion': 'lots of different types of entertainment', 'sentiment': 'positive'}, {'aspect': 'greyhound racing', 'opinion': 'lots of different types of entertainment', 'sentiment': 'positive'}, {'aspect': 'pokies', 'opinion': 'lots of different types of entertainment', 'sentiment': 'positive'}, {'aspect': 'bingo', 'opinion': 'lots of different types of entertainment', 'sentiment': 'positive'}]} | L6: {'sentence': 'Nice atmosphere , lots of different types of entertainment from sports betting , horse racing , greyhound racing , pokies , bingo and more . …', 'IOB': ['O', 'B-ASP', 'O', 'O', 'O', 'O', 'O', 'O', 'B-ASP', 'O', 'O', 'O', 'O', 'O', 'O', 'O', 'O', 'O', 'O', 'O', 'O', 'O', 'O', 'O', 'O', 'O'], 'tokens': ['Nice', 'atmosphere', ',', 'lots', 'of', 'different', 'types', 'of', 'entertainment', 'from', 'sports', 'betting', ',', 'horse', 'racing', ',', 'greyhound', 'racing', ',', 'pokies', ',', 'bingo', 'and', 'more', '.', '…'], 'aspect': ['atmosphere', 'entertainment'], 'position': [[1], [8]], 'sentiment': ['Positive', 'Positive'], 'probs': [[0.0006744035053998232, 0.00046974350698292255, 0.9988558292388916], [0.0003576667804736644, 0.00231339898891747, 0.9973289966583252]], 'confidence': [0.9989, 0.9973]} | N6: =LEN(K6)-LEN(SUBSTITUTE(K6,"{",""))-1 -> 6 | O6: 2 | P6: =_xlfn.XLOOKUP(B6,'g1'!B:B,'g1'!R:R) -> 2 | Q6: =_xlfn.XLOOKUP(B6,'g2'!B:B,'g2'!U:U) -> 2 | R6: =_xlfn.XLOOKUP(B6,'g3'!B:B,'g3'!R:R) -> 2 | S6: =_xlfn.XLOOKUP(D6,'g4'!D:D,'g4'!N:N) -> 6 | T6: =$N6-P6 -> 4 | U6: =$N6-Q6 -> 4 | V6: =$N6-R6 -> 4 | W6: =$N6-S6 -> 0 | X6: [{'aspect': 'atmosphere', 'opinion': 'Nice atmosphere', 'sentiment': 'positive'}, {'aspect': 'sports betting', 'opinion': 'lots of different types of entertainment', 'sentiment': 'positive'}, {'aspect': 'horse racing', 'opinion': 'lots of different types of entertainment', 'sentiment': 'positive'}, {'aspect': 'greyhound racing', 'opinion': 'lots of different types of entertainment', 'sentiment': 'positive'}, {'aspect': 'pokies', 'opinion': 'lots of different types of entertainment', 'sentiment': 'positive'}, {'aspect': 'bingo', 'opinion': 'lots of different types of entertainment', 'sentiment': 'positive'}] | Y6: =FIND("[{",K6) -> 43 | Z6: =FIND("category",K6) -> 68 | AA6: =Z6-Y6-2 -> 23 | AB6: atmosphere | AD6: =FIND("[{",X6) -> 1 | AE6: =FIND("opinion",X6) -> 28 | AF6: =AE6-AD6-2 -> 25 | AG6: atmosphere | AH6: =AB6=AG6 -> TRUE
A7: 1032 | B7: ChIJX4rMQkgX1GoR0HEyBXZWBA8 | C7: Luke k | D7: ChIJX4rMQkgX1GoR0HEyBXZWBA8Luke k | E7: 3 | F7: 5 days ago | G7: The facility itself is great with good infrastructure and modern amenities. Unfortunately, the customer service really lets it down, staff don’t pay attention to queries and the training team comes across as highly unprofessional. With better service, this place could be excellent. | H7: Norlane ARC | I7: 6706 | J7: 2025-10-05 | K7: {"overall_sentiment":"negative","aspects":[{"aspect":"facility","category":"facility","sentiment":"positive","evidence_span":"great"},{"aspect":"infrastructure","category":"infrastructure","sentiment":"positive","evidence_span":"good infrastructure"},{"aspect":"amenities","category":"amenities","sentiment":"positive","evidence_span":"modern amenities"},{"aspect":"customer service","category":"service","sentiment":"negative","evidence_span":"lets it down"},{"aspect":"training team","category":"staff","sentiment":"negative","evidence_span":"highly unprofessional"}]} | L7: {'sentence': 'The facility itself is great with good infrastructure and modern amenities . Unfortunately , the customer service really lets it down , staff don ’ t pay attention to queries and the training team comes across as highly unprofessional . With better service , this place could be excellent .', 'IOB': ['O', 'B-ASP', 'O', 'O', 'O', 'O', 'O', 'B-ASP', 'O', 'O', 'B-ASP', 'O', 'O', 'O', 'O', 'B-ASP', 'I-ASP', 'O', 'O', 'O', 'O', 'O', 'B-ASP', 'O', 'O', 'O', 'O', 'O', 'O', 'O', 'O', 'O', 'O', 'O', 'O', 'O', 'O', 'O', 'O', 'O', 'O', 'O', 'O', 'O', 'O', 'O', 'O', 'O', 'O', 'O'], 'tokens': ['The', 'facility', 'itself', 'is', 'great', 'with', 'good', 'infrastructure', 'and', 'modern', 'amenities', '.', 'Unfortunately', ',', 'the', 'customer', 'service', 'really', 'lets', 'it', 'down', ',', 'staff', 'don', '’', 't', 'pay', 'attention', 'to', 'queries', 'and', 'the', 'training', 'team', 'comes', 'across', 'as', 'highly', 'unprofessional', '.', 'With', 'better', 'service', ',', 'this', 'place', 'could', 'be', 'excellent', '.'], 'aspect': ['facility', 'infrastructure', 'amenities', 'customer service', 'staff'], 'position': [[1], [7], [10], [15, 16], [22]], 'sentiment': ['Positive', 'Positive', 'Positive', 'Negative', 'Negative'], 'probs': [[0.006587614770978689, 0.0003718012885656208, 0.9930405616760254], [0.0012611483689397573, 0.00026064837584272027, 0.9984782338142395], [0.0016403849003836513, 0.0002667618391569704, 0.9980928301811218], [0.999022364616394, 0.000625345972366631, 0.0003523131017573178], [0.9939771890640259, 0.005713719874620438, 0.00030897592660039663]], 'confidence': [0.993, 0.9985, 0.9981, 0.999, 0.994]} | M7: 0 | N7: =LEN(K7)-LEN(SUBSTITUTE(K7,"{",""))-1 -> 5 | O7: 5 | P7: =_xlfn.XLOOKUP(B7,'g1'!B:B,'g1'!R:R) -> 6 | Q7: =_xlfn.XLOOKUP(B7,'g2'!B:B,'g2'!U:U) -> 6 | R7: =_xlfn.XLOOKUP(B7,'g3'!B:B,'g3'!R:R) -> 2 | S7: =_xlfn.XLOOKUP(D7,'g4'!D:D,'g4'!N:N) -> 6 | T7: =$N7-P7 -> -1 | U7: =$N7-Q7 -> -1 | V7: =$N7-R7 -> 3 | W7: =$N7-S7 -> -1 | X7: [{'aspect': 'facility', 'opinion': 'great', 'sentiment': 'positive'}, {'aspect': 'infrastructure', 'opinion': 'good', 'sentiment': 'positive'}, {'aspect': 'amenities', 'opinion': 'modern', 'sentiment': 'positive'}, {'aspect': 'customer service', 'opinion': 'really lets it down', 'sentiment': 'negative'}, {'aspect': 'staff', 'opinion': 'don’t pay attention', 'sentiment': 'negative'}, {'aspect': 'training team', 'opinion': 'highly unprofessional', 'sentiment': 'negative'}] | Y7: =FIND("[{",K7) -> 43 | Z7: =FIND("category",K7) -> 66 | AA7: =Z7-Y7-2 -> 21 | AB7: facility | AD7: =FIND("[{",X7) -> 1 | AE7: =FIND("opinion",X7) -> 26 | AF7: =AE7-AD7-2 -> 23 | AG7: facility | AH7: =AB7=AG7 -> TRUE
A8: 1135 | B8: ChIJW5rqSjUR1moRqbEWJXj9SnI | C8: Jamil Zaman | D8: ChIJW5rqSjUR1moRqbEWJXj9SnIJamil Zaman | E8: 1 | F8: 2 years ago | G8: Terrible palace and not community center at all. Staff is untrained and unprofessional. Pools are dirty. No place for swimming as if you do not pay for private lessons your kids are pushed into pool corner together with all other kids. … | H8: Freeway Fitness | I8: 3540 | J8: 2023-10-11 | K8: {"overall_sentiment":"negative","aspects":[{"aspect":"place","category":"facility","sentiment":"negative","evidence_span":"Terrible palace"},{"aspect":"community center","category":"facility","sentiment":"negative","evidence_span":"not community center"},{"aspect":"staff","category":"service","sentiment":"negative","evidence_span":"untrained and unprofessional"},{"aspect":"pools","category":"facility","sentiment":"negative","evidence_span":"dirty"},{"aspect":"private lessons","category":"service","sentiment":"negative","evidence_span":"private lessons"}]} | L8: {'sentence': 'Terrible palace and not community center at all . Staff is untrained and unprofessional . Pools are dirty . No place for swimming as if you do not pay for private lessons your kids are pushed into pool corner together with all other kids . …', 'IOB': ['O', 'O', 'O', 'O', 'O', 'O', 'O', 'O', 'O', 'B-ASP', 'O', 'O', 'O', 'O', 'O', 'B-ASP', 'O', 'O', 'O', 'O', 'O', 'O', 'O', 'O', 'O', 'O', 'O', 'O', 'O', 'O', 'O', 'O', 'O', 'O', 'O', 'O', 'O', 'O', 'O', 'O', 'O', 'O', 'O', 'O', 'O', 'O'], 'tokens': ['Terrible', 'palace', 'and', 'not', 'community', 'center', 'at', 'all', '.', 'Staff', 'is', 'untrained', 'and', 'unprofessional', '.', 'Pools', 'are', 'dirty', '.', 'No', 'place', 'for', 'swimming', 'as', 'if', 'you', 'do', 'not', 'pay', 'for', 'private', 'lessons', 'your', 'kids', 'are', 'pushed', 'into', 'pool', 'corner', 'together', 'with', 'all', 'other', 'kids', '.', '…'], 'aspect': ['Staff', 'Pools'], 'position': [[9], [15]], 'sentiment': ['Negative', 'Negative'], 'probs': [[0.9983999133110046, 0.001339769922196865, 0.0002603467146400362], [0.9972741007804871, 0.0024882492143660784, 0.00023768332903273404]], 'confidence': [0.9984, 0.9973]} | M8: 1 | N8: =LEN(K8)-LEN(SUBSTITUTE(K8,"{",""))-1 -> 5 | O8: 2 | P8: =_xlfn.XLOOKUP(B8,'g1'!B:B,'g1'!R:R) -> 5 | Q8: =_xlfn.XLOOKUP(B8,'g2'!B:B,'g2'!U:U) -> 5 | R8: =_xlfn.XLOOKUP(B8,'g3'!B:B,'g3'!R:R) -> 4 | S8: =_xlfn.XLOOKUP(D8,'g4'!D:D,'g4'!N:N) -> 6 | T8: =$N8-P8 -> 0 | U8: =$N8-Q8 -> 0 | V8: =$N8-R8 -> 1 | W8: =$N8-S8 -> -1 | X8: [{'aspect': 'place', 'opinion': 'terrible', 'sentiment': 'negative'}, {'aspect': 'place', 'opinion': 'not community center', 'sentiment': 'negative'}, {'aspect': 'staff', 'opinion': 'untrained', 'sentiment': 'negative'}, {'aspect': 'staff', 'opinion': 'unprofessional', 'sentiment': 'negative'}, {'aspect': 'pools', 'opinion': 'dirty', 'sentiment': 'negative'}, {'aspect': 'public swimming', 'opinion': 'no space', 'sentiment': 'negative'}] | Y8: =FIND("[{",K8) -> 43 | Z8: =FIND("category",K8) -> 63 | AA8: =Z8-Y8-2 -> 18 | AB8: palace | AD8: =FIND("[{",X8) -> 1 | AE8: =FIND("opinion",X8) -> 23 | AF8: =AE8-AD8-2 -> 20 | AG8: place | AH8: =AB8=AG8 -> FALSE
A9: 1711 | B9: ChIJj-pnCuH0OSoR78MktwDsRpg | C9: Marie Armistead | D9: ChIJj-pnCuH0OSoR78MktwDsRpgMarie Armistead | E9: 3 | F9: 7 years ago | G9: Only flat space for a couple of larger caravans but plenty smaller or tent sites. Both flushing toilets and longdrops depending where you camp. Cold showers, no potable water. | H9: Lake Poorrarecup campsite | I9: 32952 | J9: 2018-10-12 | K9: {"overall_sentiment":"negative","aspects":[{"aspect":"larger caravan space","category":"space","sentiment":"negative","evidence_span":"a couple"},{"aspect":"tent sites","category":"space","sentiment":"positive","evidence_span":"plenty"},{"aspect":"toilets","category":"amenities","sentiment":"neutral","evidence_span":"flushing toilets"},{"aspect":"showers","category":"amenities","sentiment":"negative","evidence_span":"Cold showers"},{"aspect":"water","category":"amenities","sentiment":"negative","evidence_span":"no potable water"}]} | L9: {'sentence': 'Only flat space for a couple of larger caravans but plenty smaller or tent sites . Both flushing toilets and longdrops depending where you camp . Cold showers , no potable water .', 'IOB': ['O', 'O', 'O', 'O', 'O', 'O', 'O', 'O', 'O', 'O', 'O', 'O', 'O', 'O', 'O', 'O', 'O', 'O', 'B-ASP', 'O', 'O', 'O', 'O', 'O', 'O', 'O', 'O', 'B-ASP', 'O', 'O', 'O', 'B-ASP', 'O'], 'tokens': ['Only', 'flat', 'space', 'for', 'a', 'couple', 'of', 'larger', 'caravans', 'but', 'plenty', 'smaller', 'or', 'tent', 'sites', '.', 'Both', 'flushing', 'toilets', 'and', 'longdrops', 'depending', 'where', 'you', 'camp', '.', 'Cold', 'showers', ',', 'no', 'potable', 'water', '.'], 'aspect': ['toilets', 'showers', 'water'], 'position': [[18], [27], [31]], 'sentiment': ['Neutral', 'Negative', 'Negative'], 'probs': [[0.017098605632781982, 0.9823619723320007, 0.0005393867613747716], [0.998066246509552, 0.0013780453009530902, 0.000555767968762666], [0.9972375631332397, 0.0024370152968913317, 0.00032533612102270126]], 'confidence': [0.9824, 0.9981, 0.9972]} | M9: 1 | N9: =LEN(K9)-LEN(SUBSTITUTE(K9,"{",""))-1 -> 5 | O9: 3 | P9: =_xlfn.XLOOKUP(B9,'g1'!B:B,'g1'!R:R) -> 5 | Q9: =_xlfn.XLOOKUP(B9,'g2'!B:B,'g2'!U:U) -> 5 | R9: =_xlfn.XLOOKUP(B9,'g3'!B:B,'g3'!R:R) -> 4 | S9: =_xlfn.XLOOKUP(D9,'g4'!D:D,'g4'!N:N) -> 6 | T9: =$N9-P9 -> 0 | U9: =$N9-Q9 -> 0 | V9: =$N9-R9 -> 1 | W9: =$N9-S9 -> -1 | X9: [{'aspect': 'larger caravan sites', 'opinion': 'Only flat space for a couple of larger caravans', 'sentiment': 'negative'}, {'aspect': 'smaller/tent sites', 'opinion': 'plenty smaller or tent sites', 'sentiment': 'positive'}, {'aspect': 'flushing toilets', 'opinion': 'Both flushing toilets and longdrops depending where you camp', 'sentiment': 'neutral'}, {'aspect': 'longdrops', 'opinion': 'Both flushing toilets and longdrops depending where you camp', 'sentiment': 'neutral'}, {'aspect': 'cold showers', 'opinion': 'Cold showers', 'sentiment': 'negative'}, {'aspect': 'potable water', 'opinion': 'no potable water', 'sentiment': 'negative'}] | Y9: =FIND("[{",K9) -> 43 | Z9: =FIND("category",K9) -> 78 | AA9: =Z9-Y9-2 -> 33 | AB9: caravan space | AD9: =FIND("[{",X9) -> 1 | AE9: =FIND("opinion",X9) -> 38 | AF9: =AE9-AD9-2 -> 35 | AG9: larger caravan sites | AH9: =AB9=AG9 -> FALSE
A10: 644 | B10: ChIJXTcb9KJbkWsRUAoi11ujAg8 | C10: JG R | D10: ChIJXTcb9KJbkWsRUAoi11ujAg8JG R | E10: 5 | F10: a year ago | G10: Favorite spot to do some trail runs. Beautiful, quiet and near the city. Love it. Lots of wildlife, too :koala::Tongue_sticking_out_cheeky_playful_or_blowing_a_raspberry:ir:Tongue_sticking_out_cheeky_playful_or_blowing_a_raspberry::parrot: … | H10: Whites Hill Reserve | I10: 1842 | J10: 2024-10-10 | K10: {"overall_sentiment":"positive","aspects":[{"aspect":"trail","category":"activity","sentiment":"positive","evidence_span":"trail runs"},{"aspect":"scenery","category":"environment","sentiment":"positive","evidence_span":"Beautiful"},{"aspect":"quiet","category":"ambiance","sentiment":"positive","evidence_span":"quiet"},{"aspect":"location","category":"location","sentiment":"positive","evidence_span":"near the city"},{"aspect":"wildlife","category":"nature","sentiment":"positive","evidence_span":"wildlife"}]} | L10: {'sentence': 'Favorite spot to do some trail runs . Beautiful , quiet and near the city . Love it . Lots of wildlife , too : koala : : Tongue _ sticking _ out _ cheeky _ playful _ or _ blowing _ a _ raspberry : ir : Tongue _ sticking _ out _ cheeky _ playful _ or _ blowing _ a _ raspberry : : parrot : …', 'IOB': ['O', 'B-ASP', 'O', 'O', 'O', 'O', 'O', 'O', 'O', 'O', 'O', 'O', 'O', 'O', 'O', 'O', 'O', 'O', 'O', 'O', 'O', 'O', 'O', 'O', 'O', 'O', 'O', 'O', 'O', 'O', 'O', 'O', 'O', 'O', 'O', 'O', 'O', 'O', 'O', 'O', 'O', 'O', 'O', 'O', 'O', 'O', 'O', 'O', 'O', 'O', 'O', 'O', 'O', 'O', 'O', 'O', 'O', 'O', 'O', 'O', 'O', 'O', 'O', 'O', 'O', 'O', 'O', 'O', 'O', 'O'], 'tokens': ['Favorite', 'spot', 'to', 'do', 'some', 'trail', 'runs', '.', 'Beautiful', ',', 'quiet', 'and', 'near', 'the', 'city', '.', 'Love', 'it', '.', 'Lots', 'of', 'wildlife', ',', 'too', ':', 'koala', ':', ':', 'Tongue', '_', 'sticking', '_', 'out', '_', 'cheeky', '_', 'playful', '_', 'or', '_', 'blowing', '_', 'a', '_', 'raspberry', ':', 'ir', ':', 'Tongue', '_', 'sticking', '_', 'out', '_', 'cheeky', '_', 'playful', '_', 'or', '_', 'blowing', '_', 'a', '_', 'raspberry', ':', ':', 'parrot', ':', '…'], 'aspect': ['spot'], 'position': [[1]], 'sentiment': ['Positive'], 'probs': [[0.0003489186055958271, 0.0006280795205384493, 0.9990229606628418]], 'confidence': [0.999]} | M10: 1 | N10: =LEN(K10)-LEN(SUBSTITUTE(K10,"{",""))-1 -> 5 | O10: 1 | P10: =_xlfn.XLOOKUP(B10,'g1'!B:B,'g1'!R:R) -> 5 | Q10: =_xlfn.XLOOKUP(B10,'g2'!B:B,'g2'!U:U) -> 5 | R10: =_xlfn.XLOOKUP(B10,'g3'!B:B,'g3'!R:R) -> 4 | S10: =_xlfn.XLOOKUP(D10,'g4'!D:D,'g4'!N:N) -> 6 | T10: =$N10-P10 -> 0 | U10: =$N10-Q10 -> 0 | V10: =$N10-R10 -> 1 | W10: =$N10-S10 -> -1 | X10: [{'aspect': 'trails', 'opinion': 'favorite', 'sentiment': 'positive'}, {'aspect': 'wildlife', 'opinion': 'lots of', 'sentiment': 'positive'}, {'aspect': 'scenery', 'opinion': 'beautiful', 'sentiment': 'positive'}, {'aspect': 'ambience', 'opinion': 'quiet', 'sentiment': 'positive'}, {'aspect': 'location', 'opinion': 'near the city', 'sentiment': 'positive'}, {'aspect': 'overall experience', 'opinion': 'love it', 'sentiment': 'positive'}] | Y10: =FIND("[{",K10) -> 43 | Z10: =FIND("category",K10) -> 63 | AA10: =Z10-Y10-2 -> 18 | AB10: trail runs | AD10: =FIND("[{",X10) -> 1 | AE10: =FIND("opinion",X10) -> 24 | AF10: =AE10-AD10-2 -> 21 | AG10: trails | AH10: =AB10=AG10 -> FALSE
A11: 679 | B11: ChIJS9ZKpBU81moRtCCzzU2_fcA | C11: Daniel YANG | D11: ChIJS9ZKpBU81moRtCCzzU2_fcADaniel YANG | E11: 3 | F11: 7 years ago | G11: Not great place for kids birthday party. The host is not experienced for kids party, everything is very slow, food, party organize, birthday cake serve. Very noisy in function room, it's a big function room to share with other parties, one … | H11: Zone Bowling Castle Hill | I11: 1374 | J11: 2018-10-12 | K11: {"overall_sentiment":"negative","aspects":[{"aspect":"host","category":"service","sentiment":"negative","evidence_span":"not experienced"},{"aspect":"food","category":"food","sentiment":"negative","evidence_span":"food"},{"aspect":"organization","category":"service","sentiment":"negative","evidence_span":"party organize"},{"aspect":"cake serve","category":"food","sentiment":"negative","evidence_span":"birthday cake serve"},{"aspect":"noise","category":"ambience","sentiment":"negative","evidence_span":"Very noisy"}]} | L11: {'sentence': "Not great place for kids birthday party . The host is not experienced for kids party , everything is very slow , food , party organize , birthday cake serve . Very noisy in function room , it ' s a big function room to share with other parties , one …", 'IOB': ['O', 'O', 'O', 'O', 'O', 'O', 'O', 'O', 'O', 'B-ASP', 'O', 'O', 'O', 'O', 'O', 'O', 'O', 'O', 'O', 'O', 'O', 'O', 'B-ASP', 'O', 'O', 'O', 'O', 'O', 'O', 'O', 'O', 'O', 'O', 'O', 'O', 'B-ASP', 'O', 'O', 'O', 'O', 'O', 'O', 'O', 'O', 'O', 'O', 'O', 'O', 'O', 'O', 'O', 'O'], 'tokens': ['Not', 'great', 'place', 'for', 'kids', 'birthday', 'party', '.', 'The', 'host', 'is', 'not', 'experienced', 'for', 'kids', 'party', ',', 'everything', 'is', 'very', 'slow', ',', 'food', ',', 'party', 'organize', ',', 'birthday', 'cake', 'serve', '.', 'Very', 'noisy', 'in', 'function', 'room', ',', 'it', "'", 's', 'a', 'big', 'function', 'room', 'to', 'share', 'with', 'other', 'parties', ',', 'one', '…'], 'aspect': ['host', 'food', 'room'], 'position': [[9], [22], [35]], 'sentiment': ['Negative', 'Negative', 'Negative'], 'probs': [[0.9945231676101685, 0.005103238858282566, 0.0003736235958058387], [0.8989600539207458, 0.10058768838644028, 0.0004521906084846705], [0.9865661263465881, 0.011451512575149536, 0.0019823985639959574]], 'confidence': [0.9945, 0.899, 0.9866]} | M11: 1 | N11: =LEN(K11)-LEN(SUBSTITUTE(K11,"{",""))-1 -> 5 | O11: 3 | P11: =_xlfn.XLOOKUP(B11,'g1'!B:B,'g1'!R:R) -> 6 | Q11: =_xlfn.XLOOKUP(B11,'g2'!B:B,'g2'!U:U) -> 6 | R11: =_xlfn.XLOOKUP(B11,'g3'!B:B,'g3'!R:R) -> 4 | S11: =_xlfn.XLOOKUP(D11,'g4'!D:D,'g4'!N:N) -> 6 | T11: =$N11-P11 -> -1 | U11: =$N11-Q11 -> -1 | V11: =$N11-R11 -> 1 | W11: =$N11-S11 -> -1 | X11: [{'aspect': 'host', 'opinion': 'not experienced', 'sentiment': 'negative'}, {'aspect': 'service speed', 'opinion': 'very slow', 'sentiment': 'negative'}, {'aspect': 'function room', 'opinion': 'very noisy', 'sentiment': 'negative'}, {'aspect': 'kids birthday party', 'opinion': 'not great', 'sentiment': 'negative'}, {'aspect': 'party organization', 'opinion': 'very slow', 'sentiment': 'negative'}, {'aspect': 'birthday cake service', 'opinion': 'very slow', 'sentiment': 'negative'}] | Y11: =FIND("[{",K11) -> 43 | Z11: =FIND("category",K11) -> 62 | AA11: =Z11-Y11-2 -> 17 | AB11: host | AD11: =FIND("[{",X11) -> 1 | AE11: =FIND("opinion",X11) -> 22 | AF11: =AE11-AD11-2 -> 19 | AG11: host | AH11: =AB11=AG11 -> TRUE
A12: 698 | B12: ChIJ16bsf211wmsRULU9xLIf--A | C12: Sam “Sam” Sam | D12: ChIJ16bsf211wmsRULU9xLIf--ASam “Sam” Sam | E12: 3 | F12: 5 years ago | G12: Very beautiful and clean. Almost, covered with huge trees. Not recommended dusk time, as mosquitos are very active specially when it's not breezy. Good for family and friends gathering. Spacious car park. | H12: Barney Point Beach | I12: 13063 | J12: 2020-10-11 | K12: {"overall_sentiment":"positive","aspects":[{"aspect":"beauty","category":"aesthetics","sentiment":"positive","evidence_span":"beautiful"},{"aspect":"cleanliness","category":"cleanliness","sentiment":"positive","evidence_span":"clean"},{"aspect":"mosquitos","category":"pests","sentiment":"negative","evidence_span":"mosquitos"},{"aspect":"family gatherings","category":"suitability","sentiment":"positive","evidence_span":"Good for family"},{"aspect":"parking","category":"parking","sentiment":"positive","evidence_span":"Spacious car park"}]} | L12: {'sentence': "Very beautiful and clean . Almost , covered with huge trees . Not recommended dusk time , as mosquitos are very active specially when it ' s not breezy . Good for family and friends gathering . Spacious car park .", 'IOB': ['O', 'O', 'O', 'O', 'O', 'O', 'O', 'O', 'O', 'O', 'O', 'O', 'O', 'O', 'O', 'O', 'O', 'O', 'O', 'O', 'O', 'O', 'O', 'O', 'O', 'O', 'O', 'O', 'O', 'O', 'O', 'O', 'O', 'O', 'O', 'O', 'O', 'O', 'O', 'B-ASP', 'O'], 'tokens': ['Very', 'beautiful', 'and', 'clean', '.', 'Almost', ',', 'covered', 'with', 'huge', 'trees', '.', 'Not', 'recommended', 'dusk', 'time', ',', 'as', 'mosquitos', 'are', 'very', 'active', 'specially', 'when', 'it', "'", 's', 'not', 'breezy', '.', 'Good', 'for', 'family', 'and', 'friends', 'gathering', '.', 'Spacious', 'car', 'park', '.'], 'aspect': ['park'], 'position': [[39]], 'sentiment': ['Positive'], 'probs': [[0.00037158484337851405, 0.0003445502952672541, 0.9992839694023132]], 'confidence': [0.9993]} | M12: 1 | N12: 5 | O12: 1 | P12: =_xlfn.XLOOKUP(B12,'g1'!B:B,'g1'!R:R) -> 8 | Q12: =_xlfn.XLOOKUP(B12,'g2'!B:B,'g2'!U:U) -> 8 | R12: =_xlfn.XLOOKUP(B12,'g3'!B:B,'g3'!R:R) -> 5 | S12: =_xlfn.XLOOKUP(D12,'g4'!D:D,'g4'!N:N) -> 6 | T12: =$N12-P12 -> -3 | U12: =$N12-Q12 -> -3 | V12: =$N12-R12 -> 0 | W12: =$N12-S12 -> -1 | X12: [{'aspect': 'beauty', 'opinion': 'Very beautiful', 'sentiment': 'positive'}, {'aspect': 'clean', 'opinion': 'clean', 'sentiment': 'positive'}, {'aspect': 'trees', 'opinion': 'covered with huge trees', 'sentiment': 'positive'}, {'aspect': 'mosquitoes', 'opinion': "very active specially when it's not breezy", 'sentiment': 'negative'}, {'aspect': 'family and friends gathering', 'opinion': 'Good for', 'sentiment': 'positive'}, {'aspect': 'car park', 'opinion': 'Spacious', 'sentiment': 'positive'}] | Y12: =FIND("[{",K12) -> 43 | Z12: =FIND("category",K12) -> 64 | AA12: =Z12-Y12-2 -> 19 | AB12: beauty | AD12: =FIND("[{",X12) -> 1 | AE12: =FIND("opinion",X12) -> 24 | AF12: =AE12-AD12-2 -> 21 | AG12: beauty | AH12: =AB12=AG12 -> TRUE
A13: 744 | B13: ChIJT6u_11tRDWsR8Jzy-Wh9AQ8 | C13: Milena Lozanova | D13: ChIJT6u_11tRDWsR8Jzy-Wh9AQ8Milena Lozanova | E13: 5 | F13: 7 years ago | G13: Love hiking there - the bushland meets rivers and creeks makes for great views and variety! Plenty of bushwalking tracks. | H13: Ku-ring-gai Chase National Park | I13: 426 | J13: 2018-10-12 | K13: {"overall_sentiment":"positive","aspects":[{"aspect":"hiking","category":"activity","sentiment":"positive","evidence_span":"Love hiking"},{"aspect":"views","category":"scenery","sentiment":"positive","evidence_span":"great views"},{"aspect":"variety","category":"diversity","sentiment":"positive","evidence_span":"variety"},{"aspect":"tracks","category":"trail","sentiment":"positive","evidence_span":"bushwalking tracks"}]} | L13: {'sentence': 'Love hiking there - the bushland meets rivers and creeks makes for great views and variety ! Plenty of bushwalking tracks .', 'IOB': ['O', 'O', 'O', 'O', 'O', 'O', 'O', 'O', 'O', 'O', 'O', 'O', 'O', 'B-ASP', 'O', 'O', 'O', 'O', 'O', 'O', 'O', 'O'], 'tokens': ['Love', 'hiking', 'there', '-', 'the', 'bushland', 'meets', 'rivers', 'and', 'creeks', 'makes', 'for', 'great', 'views', 'and', 'variety', '!', 'Plenty', 'of', 'bushwalking', 'tracks', '.'], 'aspect': ['views'], 'position': [[13]], 'sentiment': ['Positive'], 'probs': [[0.00015378743410110474, 0.0007074762252159417, 0.9991387128829956]], 'confidence': [0.9991]} | M13: 1 | N13: =LEN(K13)-LEN(SUBSTITUTE(K13,"{",""))-1 -> 4 | O13: 1 | P13: =_xlfn.XLOOKUP(B13,'g1'!B:B,'g1'!R:R) -> 4 | Q13: =_xlfn.XLOOKUP(B13,'g2'!B:B,'g2'!U:U) -> 4 | R13: =_xlfn.XLOOKUP(B13,'g3'!B:B,'g3'!R:R) -> 2 | S13: =_xlfn.XLOOKUP(D13,'g4'!D:D,'g4'!N:N) -> 6 | T13: =$N13-P13 -> 0 | U13: =$N13-Q13 -> 0 | V13: =$N13-R13 -> 2 | W13: =$N13-S13 -> -2 | X13: [{'aspect': 'hiking', 'opinion': 'Love hiking', 'sentiment': 'positive'}, {'aspect': 'bushland, rivers and creeks', 'opinion': 'meets rivers and creeks makes for great views and variety', 'sentiment': 'positive'}, {'aspect': 'bushland', 'opinion': 'meets rivers and creeks makes for great views and variety', 'sentiment': 'positive'}, {'aspect': 'rivers', 'opinion': 'meets rivers and creeks makes for great views and variety', 'sentiment': 'positive'}, {'aspect': 'creeks', 'opinion': 'meets rivers and creeks makes for great views and variety', 'sentiment': 'positive'}, {'aspect': 'bushwalking tracks', 'opinion': 'Plenty of bushwalking tracks', 'sentiment': 'positive'}] | Y13: =FIND("[{",K13) -> 43 | Z13: =FIND("category",K13) -> 64 | AA13: =Z13-Y13-2 -> 19 | AB13: hiking | AD13: =FIND("[{",X13) -> 1 | AE13: =FIND("opinion",X13) -> 24 | AF13: =AE13-AD13-2 -> 21 | AG13: hiking | AH13: =AB13=AG13 -> TRUE
A14: 1030 | B14: ChIJYdTsfgysEmsR183dKkF4AGs | C14: XOZTCATPREZ | D14: ChIJYdTsfgysEmsR183dKkF4AGsXOZTCATPREZ | E14: 3 | F14: 6 years ago | G14: Toxicly busy and shocking parking, especially the cost. Go to a good beach with waves instead. So much money for flat water....... It's like alcohol free beer! Totally overrated! | H14: Balmoral Beach | I14: 446 | J14: 2019-10-12 | K14: {"overall_sentiment":"negative","aspects":[{"aspect":"crowd","category":"crowding","sentiment":"negative","evidence_span":"Toxicly busy"},{"aspect":"parking","category":"parking","sentiment":"negative","evidence_span":"shocking parking"},{"aspect":"cost","category":"price","sentiment":"negative","evidence_span":"cost"},{"aspect":"water","category":"water quality","sentiment":"negative","evidence_span":"flat water"}]} | L14: {'sentence': "Toxicly busy and shocking parking , especially the cost . Go to a good beach with waves instead . So much money for flat water . . . . . . . It ' s like alcohol free beer ! Totally overrated !", 'IOB': ['O', 'O', 'O', 'O', 'O', 'O', 'O', 'O', 'B-ASP', 'O', 'O', 'O', 'O', 'O', 'O', 'O', 'O', 'O', 'O', 'O', 'O', 'B-ASP', 'O', 'O', 'O', 'O', 'O', 'O', 'O', 'O', 'O', 'O', 'O', 'O', 'O', 'O', 'O', 'O', 'O', 'O', 'O', 'O', 'O'], 'tokens': ['Toxicly', 'busy', 'and', 'shocking', 'parking', ',', 'especially', 'the', 'cost', '.', 'Go', 'to', 'a', 'good', 'beach', 'with', 'waves', 'instead', '.', 'So', 'much', 'money', 'for', 'flat', 'water', '.', '.', '.', '.', '.', '.', '.', 'It', "'", 's', 'like', 'alcohol', 'free', 'beer', '!', 'Totally', 'overrated', '!'], 'aspect': ['cost', 'money'], 'position': [[8], [21]], 'sentiment': ['Negative', 'Negative'], 'probs': [[0.990211009979248, 0.001981730107218027, 0.007807331159710884], [0.9891184568405151, 0.0011727664386853576, 0.009708747267723083]], 'confidence': [0.9902, 0.9891]} | M14: 1 | N14: =LEN(K14)-LEN(SUBSTITUTE(K14,"{",""))-1 -> 4 | O14: 2 | P14: =_xlfn.XLOOKUP(B14,'g1'!B:B,'g1'!R:R) -> 5 | Q14: =_xlfn.XLOOKUP(B14,'g2'!B:B,'g2'!U:U) -> 3 | R14: =_xlfn.XLOOKUP(B14,'g3'!B:B,'g3'!R:R) -> 3 | S14: =_xlfn.XLOOKUP(D14,'g4'!D:D,'g4'!N:N) -> 6 | T14: =$N14-P14 -> -1 | U14: =$N14-Q14 -> 1 | V14: =$N14-R14 -> 1 | W14: =$N14-S14 -> -2 | X14: [{'aspect': 'busy', 'opinion': 'Toxicly busy', 'sentiment': 'negative'}, {'aspect': 'parking', 'opinion': 'shocking parking', 'sentiment': 'negative'}, {'aspect': 'cost', 'opinion': 'so much money', 'sentiment': 'negative'}, {'aspect': 'water', 'opinion': 'flat water', 'sentiment': 'neutral'}, {'aspect': 'waves', 'opinion': 'no waves', 'sentiment': 'neutral'}, {'aspect': 'value', 'opinion': 'Totally overrated', 'sentiment': 'negative'}] | Y14: =FIND("[{",K14) -> 43 | Z14: =FIND("category",K14) -> 63 | AA14: =Z14-Y14-2 -> 18 | AB14: crowd | AD14: =FIND("[{",X14) -> 1 | AE14: =FIND("opinion",X14) -> 22 | AF14: =AE14-AD14-2 -> 19 | AG14: busy | AH14: =AB14=AG14 -> FALSE
A15: 1195 | B15: ChIJe2yce2nOpWsRavwI_SaXFNM | C15: Athfos | D15: ChIJe2yce2nOpWsRavwI_SaXFNMAthfos | E15: 3 | F15: 2 years ago | G15: A nice complex of pools and grassed outdoors area with one small Great Artesian Basin pool. Nice temperature around 40 degrees but was probably a little less. Not a completely natural water feed as the water is filtered and chlorinated because of the safety police. Opens 7.30am to Noon weekdays only. | H15: Mungindi Swimming Pool | I15: 39615 | J15: 2023-10-11 | K15: {"overall_sentiment":"positive","aspects":[{"aspect":"pool complex","category":"amenities","sentiment":"positive","evidence_span":"nice complex"},{"aspect":"temperature","category":"comfort","sentiment":"positive","evidence_span":"Nice temperature"},{"aspect":"water","category":"hygiene","sentiment":"negative","evidence_span":"filtered and chlorinated"},{"aspect":"hours","category":"access","sentiment":"neutral","evidence_span":"weekdays only"}]} | L15: {'sentence': 'A nice complex of pools and grassed outdoors area with one small Great Artesian Basin pool . Nice temperature around 40 degrees but was probably a little less . Not a completely natural water feed as the water is filtered and chlorinated because of the safety police . Opens 7 . 30am to Noon weekdays only .', 'IOB': ['O', 'O', 'O', 'O', 'O', 'O', 'O', 'O', 'B-ASP', 'O', 'O', 'O', 'O', 'O', 'O', 'O', 'O', 'O', 'B-ASP', 'O', 'O', 'O', 'O', 'O', 'O', 'O', 'O', 'O', 'O', 'O', 'O', 'O', 'O', 'O', 'O', 'O', 'O', 'O', 'O', 'O', 'O', 'O', 'O', 'O', 'O', 'O', 'O', 'O', 'O', 'O', 'O', 'O', 'O', 'O', 'O', 'O', 'O'], 'tokens': ['A', 'nice', 'complex', 'of', 'pools', 'and', 'grassed', 'outdoors', 'area', 'with', 'one', 'small', 'Great', 'Artesian', 'Basin', 'pool', '.', 'Nice', 'temperature', 'around', '40', 'degrees', 'but', 'was', 'probably', 'a', 'little', 'less', '.', 'Not', 'a', 'completely', 'natural', 'water', 'feed', 'as', 'the', 'water', 'is', 'filtered', 'and', 'chlorinated', 'because', 'of', 'the', 'safety', 'police', '.', 'Opens', '7', '.', '30am', 'to', 'Noon', 'weekdays', 'only', '.'], 'aspect': ['area', 'temperature'], 'position': [[8], [18]], 'sentiment': ['Neutral', 'Positive'], 'probs': [[0.0023743740748614073, 0.5699761509895325, 0.42764949798583984], [0.02284722961485386, 0.001875527435913682, 0.9752771854400635]], 'confidence': [0.57, 0.9753]} | M15: 1 | N15: 4 | O15: 2 | P15: =_xlfn.XLOOKUP(B15,'g1'!B:B,'g1'!R:R) -> 6 | Q15: =_xlfn.XLOOKUP(B15,'g2'!B:B,'g2'!U:U) -> 8 | R15: =_xlfn.XLOOKUP(B15,'g3'!B:B,'g3'!R:R) -> 4 | S15: =_xlfn.XLOOKUP(D15,'g4'!D:D,'g4'!N:N) -> 6 | T15: =$N15-P15 -> -2 | U15: =$N15-Q15 -> -4 | V15: =$N15-R15 -> 0 | W15: =$N15-S15 -> -2 | X15: [{'aspect': 'pool complex', 'opinion': 'A nice complex of pools', 'sentiment': 'positive'}, {'aspect': 'grassed outdoors area', 'opinion': 'nice grassed outdoors area', 'sentiment': 'positive'}, {'aspect': 'Great Artesian Basin pool', 'opinion': 'one small Great Artesian Basin pool', 'sentiment': 'neutral'}, {'aspect': 'water quality', 'opinion': 'water is filtered and chlorinated because of the safety police', 'sentiment': 'negative'}, {'aspect': 'operating hours', 'opinion': 'Opens 7.30am to Noon weekdays only', 'sentiment': 'negative'}, {'aspect': 'temperature', 'opinion': 'Nice temperature around 40 degrees but was probably a little less', 'sentiment': 'positive'}] | Y15: =FIND("[{",K15) -> 43 | Z15: =FIND("category",K15) -> 70 | AA15: =Z15-Y15-2 -> 25 | AB15: complex | AD15: =FIND("[{",X15) -> 1 | AE15: =FIND("opinion",X15) -> 30 | AF15: =AE15-AD15-2 -> 27 | AG15: pool complex | AH15: =AB15=AG15 -> FALSE
A16: 1367 | B16: ChIJBZmFK_tDkWsRb6hNhBgbJ-U | C16: Syed | D16: ChIJBZmFK_tDkWsRb6hNhBgbJ-USyed | E16: 5 | F16: 7 years ago | G16: Amazing place for people from any faith, colour or background. A very multi cultural environment. Buzzing with youth and kids. A great place for learning and development. A venue for humanitarian and social work. A unity centre in true sense. | H16: Australian Centre for Unity: Slacks Creek Mosque - IPDC QLD | I16: 15206 | J16: 2018-10-12 | K16: {"overall_sentiment":"positive","aspects":[{"aspect":"inclusivity","category":"culture","sentiment":"positive","evidence_span":"any faith"},{"aspect":"environment","category":"ambiance","sentiment":"positive","evidence_span":"multi cultural environment"},{"aspect":"youth","category":"audience","sentiment":"positive","evidence_span":"youth and kids"},{"aspect":"unity centre","category":"venue","sentiment":"positive","evidence_span":"unity centre"}]} | L16: {'sentence': 'Amazing place for people from any faith , colour or background . A very multi cultural environment . Buzzing with youth and kids . A great place for learning and development . A venue for humanitarian and social work . A unity centre in true sense .', 'IOB': ['O', 'B-ASP', 'O', 'O', 'O', 'O', 'O', 'O', 'O', 'O', 'O', 'O', 'O', 'O', 'O', 'O', 'B-ASP', 'O', 'O', 'O', 'O', 'O', 'O', 'O', 'O', 'O', 'O', 'O', 'O', 'O', 'O', 'O', 'O', 'O', 'O', 'O', 'O', 'O', 'O', 'O', 'O', 'O', 'O', 'O', 'O', 'O', 'O'], 'tokens': ['Amazing', 'place', 'for', 'people', 'from', 'any', 'faith', ',', 'colour', 'or', 'background', '.', 'A', 'very', 'multi', 'cultural', 'environment', '.', 'Buzzing', 'with', 'youth', 'and', 'kids', '.', 'A', 'great', 'place', 'for', 'learning', 'and', 'development', '.', 'A', 'venue', 'for', 'humanitarian', 'and', 'social', 'work', '.', 'A', 'unity', 'centre', 'in', 'true', 'sense', '.'], 'aspect': ['place', 'environment'], 'position': [[1], [16]], 'sentiment': ['Positive', 'Positive'], 'probs': [[0.00046748650493100286, 0.00039927742909640074, 0.999133288860321], [0.00022772210650146008, 0.00037490681279450655, 0.9993973970413208]], 'confidence': [0.9991, 0.9994]} | M16: 1 | N16: =LEN(K16)-LEN(SUBSTITUTE(K16,"{",""))-1 -> 4 | O16: 2 | P16: =_xlfn.XLOOKUP(B16,'g1'!B:B,'g1'!R:R) -> 6 | Q16: =_xlfn.XLOOKUP(B16,'g2'!B:B,'g2'!U:U) -> 5 | R16: =_xlfn.XLOOKUP(B16,'g3'!B:B,'g3'!R:R) -> 6 | S16: =_xlfn.XLOOKUP(D16,'g4'!D:D,'g4'!N:N) -> 6 | T16: =$N16-P16 -> -2 | U16: =$N16-Q16 -> -1 | V16: =$N16-R16 -> -2 | W16: =$N16-S16 -> -2 | X16: [{'aspect': 'inclusivity', 'opinion': 'Amazing place for people from any faith, colour or background', 'sentiment': 'positive'}, {'aspect': 'multicultural environment', 'opinion': 'A very multi cultural environment', 'sentiment': 'positive'}, {'aspect': 'youth and kids', 'opinion': 'Buzzing with youth and kids', 'sentiment': 'positive'}, {'aspect': 'learning and development', 'opinion': 'a great place for learning and development', 'sentiment': 'positive'}, {'aspect': 'humanitarian and social work', 'opinion': 'a venue for humanitarian and social work', 'sentiment': 'positive'}, {'aspect': 'unity centre', 'opinion': 'A unity centre in true sense', 'sentiment': 'positive'}] | Y16: =FIND("[{",K16) -> 43 | Z16: =FIND("category",K16) -> 69 | AA16: =Z16-Y16-2 -> 24 | AB16: diversity | AD16: =FIND("[{",X16) -> 1 | AE16: =FIND("opinion",X16) -> 29 | AF16: =AE16-AD16-2 -> 26 | AG16: inclusivity | AH16: =AB16=AG16 -> FALSE
A17: 1870 | B17: ChIJN0j6yrJQkWsR14GqlOLB00E | C17: Amanda Maslin | D17: ChIJN0j6yrJQkWsR14GqlOLB00EAmanda Maslin | E17: 3 | F17: 6 years ago | G17: A funky place and byo snacks and wine. Not a lot of space for either alongside paint/brushes. Also for $50, I would expect more instruction on how and what to paint. It's a very free-form, hands-off experience. The focus is more on socialising and listening to music/drinking while painting. | H17: Brush & Barrel | I17: 26184 | J17: 2019-10-12 | K17: {"overall_sentiment":"negative","aspects":[{"aspect":"ambiance","category":"ambiance","sentiment":"positive","evidence_span":"funky place"},{"aspect":"space","category":"facility","sentiment":"negative","evidence_span":"Not a lot"},{"aspect":"instruction","category":"service","sentiment":"negative","evidence_span":"more instruction"},{"aspect":"experience","category":"format","sentiment":"negative","evidence_span":"hands-off"}]} | L17: {'sentence': "A funky place and byo snacks and wine . Not a lot of space for either alongside paint / brushes . Also for $ 50 , I would expect more instruction on how and what to paint . It ' s a very free - form , hands - off experience . The focus is more on socialising and listening to music / drinking while painting .", 'IOB': ['O', 'O', 'B-ASP', 'O', 'O', 'O', 'O', 'B-ASP', 'O', 'O', 'O', 'O', 'O', 'O', 'O', 'O', 'O', 'O', 'O', 'O', 'O', 'O', 'O', 'O', 'O', 'O', 'O', 'O', 'O', 'O', 'O', 'O', 'O', 'O', 'O', 'O', 'O', 'O', 'O', 'O', 'O', 'O', 'O', 'O', 'O', 'O', 'O', 'O', 'O', 'O', 'O', 'O', 'O', 'O', 'O', 'O', 'O', 'O', 'O', 'O', 'O', 'O', 'O', 'O', 'O', 'O', 'O'], 'tokens': ['A', 'funky', 'place', 'and', 'byo', 'snacks', 'and', 'wine', '.', 'Not', 'a', 'lot', 'of', 'space', 'for', 'either', 'alongside', 'paint', '/', 'brushes', '.', 'Also', 'for', '$', '50', ',', 'I', 'would', 'expect', 'more', 'instruction', 'on', 'how', 'and', 'what', 'to', 'paint', '.', 'It', "'", 's', 'a', 'very', 'free', '-', 'form', ',', 'hands', '-', 'off', 'experience', '.', 'The', 'focus', 'is', 'more', 'on', 'socialising', 'and', 'listening', 'to', 'music', '/', 'drinking', 'while', 'painting', '.'], 'aspect': ['place', 'wine'], 'position': [[2], [7]], 'sentiment': ['Positive', 'Neutral'], 'probs': [[0.0022751218639314175, 0.002708323998376727, 0.9950165152549744], [0.002928764559328556, 0.9933831095695496, 0.003688059514388442]], 'confidence': [0.995, 0.9934]} | M17: 1 | N17: =LEN(K17)-LEN(SUBSTITUTE(K17,"{",""))-1 -> 4 | O17: 2 | P17: =_xlfn.XLOOKUP(B17,'g1'!B:B,'g1'!R:R) -> 7 | Q17: =_xlfn.XLOOKUP(B17,'g2'!B:B,'g2'!U:U) -> 6 | R17: =_xlfn.XLOOKUP(B17,'g3'!B:B,'g3'!R:R) -> 6 | S17: =_xlfn.XLOOKUP(D17,'g4'!D:D,'g4'!N:N) -> 6 | T17: =$N17-P17 -> -3 | U17: =$N17-Q17 -> -2 | V17: =$N17-R17 -> -2 | W17: =$N17-S17 -> -2 | X17: [{'aspect': 'ambiance', 'opinion': 'funky', 'sentiment': 'positive'}, {'aspect': 'space', 'opinion': 'not a lot of space', 'sentiment': 'negative'}, {'aspect': 'instruction', 'opinion': 'more instruction on how and what to paint', 'sentiment': 'negative'}, {'aspect': 'experience', 'opinion': 'very free-form, hands-off experience', 'sentiment': 'negative'}, {'aspect': 'BYO policy', 'opinion': 'byo snacks and wine', 'sentiment': 'positive'}, {'aspect': 'price', 'opinion': '$50', 'sentiment': 'negative'}] | Y17: =FIND("[{",K17) -> 43 | Z17: =FIND("category",K17) -> 66 | AA17: =Z17-Y17-2 -> 21 | AB17: ambiance | AD17: =FIND("[{",X17) -> 1 | AE17: =FIND("opinion",X17) -> 26 | AF17: =AE17-AD17-2 -> 23 | AG17: ambiance | AH17: =AB17=AG17 -> TRUE
A18: 636 | B18: ChIJp4-myXZKzWoRhOrDuoaamaY | C18: Dawn Elizabeth Anderson | D18: ChIJp4-myXZKzWoRhOrDuoaamaYDawn Elizabeth Anderson | E18: 5 | F18: 6 years ago | G18: Beautiful nature walks, we saw baby emu's, koalas and a snake! Vegetation and sounds of the bush were lovely. | H18: Tower Hill Park Boundary | I18: 35482 | J18: 2019-10-12 | K18: {"overall_sentiment":"positive","aspects":[{'aspect': "baby emu's","category":"environment", 'opinion': 'saw', 'sentiment': 'positive'}, {'aspect': 'koalas',"category":"environment", 'opinion': 'saw', 'sentiment': 'positive'}, {'aspect': 'a snake',"category":"environment", 'opinion': 'saw', 'sentiment': 'positive'},{"aspect":"nature walks","category":"activities","sentiment":"positive","evidence_span":"Beautiful nature walks"},{"aspect":"vegetation","category":"environment","sentiment":"positive","evidence_span":"were lovely"},{"aspect":"sounds","category":"ambiance","sentiment":"positive","evidence_span":"were lovely"}]} | L18: {'sentence': "Beautiful nature walks , we saw baby emu ' s , koalas and a snake ! Vegetation and sounds of the bush were lovely .", 'IOB': ['O', 'B-ASP', 'O', 'O', 'O', 'O', 'O', 'O', 'O', 'O', 'O', 'O', 'O', 'O', 'B-ASP', 'O', 'O', 'O', 'B-ASP', 'O', 'O', 'O', 'O', 'O', 'O'], 'tokens': ['Beautiful', 'nature', 'walks', ',', 'we', 'saw', 'baby', 'emu', "'", 's', ',', 'koalas', 'and', 'a', 'snake', '!', 'Vegetation', 'and', 'sounds', 'of', 'the', 'bush', 'were', 'lovely', '.'], 'aspect': ['nature', 'snake', 'sounds'], 'position': [[1], [14], [18]], 'sentiment': ['Positive', 'Neutral', 'Positive'], 'probs': [[0.0002940867852885276, 0.0002645606582518667, 0.9994413256645203], [0.0002947285247500986, 0.9736195802688599, 0.026085680350661278], [0.0003183631633874029, 0.019295671954751015, 0.980385959148407]], 'confidence': [0.9994, 0.9736, 0.9804]} | N18: =LEN(K18)-LEN(SUBSTITUTE(K18,"{",""))-1 -> 6 | O18: 3 | P18: =_xlfn.XLOOKUP(B18,'g1'!B:B,'g1'!R:R) -> 3 | Q18: =_xlfn.XLOOKUP(B18,'g2'!B:B,'g2'!U:U) -> 3 | R18: =_xlfn.XLOOKUP(B18,'g3'!B:B,'g3'!R:R) -> 3 | S18: =_xlfn.XLOOKUP(D18,'g4'!D:D,'g4'!N:N) -> 6 | T18: =$N18-P18 -> 3 | U18: =$N18-Q18 -> 3 | V18: =$N18-R18 -> 3 | W18: =$N18-S18 -> 0 | X18: [{'aspect': "baby emu's", 'opinion': 'saw', 'sentiment': 'positive'}, {'aspect': 'koalas', 'opinion': 'saw', 'sentiment': 'positive'}, {'aspect': 'a snake', 'opinion': 'saw', 'sentiment': 'positive'}, {'aspect': 'vegetation', 'opinion': 'lovely', 'sentiment': 'positive'}, {'aspect': 'sounds of the bush', 'opinion': 'lovely', 'sentiment': 'positive'}, {'aspect': 'nature walks', 'opinion': 'Beautiful', 'sentiment': 'positive'}] | Y18: =FIND("[{",K18) -> 43 | Z18: =FIND("category",K18) -> 69 | AA18: =Z18-Y18-2 -> 24 | AB18: nature walks | AD18: =FIND("[{",X18) -> 1 | AE18: =FIND("opinion",X18) -> 28 | AF18: =AE18-AD18-2 -> 25 | AG18: baby emu's | AH18: =AB18=AG18 -> FALSE
A19: 1837 | B19: ChIJj_UC5JnPsGoRQOi5RVU2Aw8 | C19: Vahid Ch. | D19: ChIJj_UC5JnPsGoRQOi5RVU2Aw8Vahid Ch. | E19: 4 | F19: 3 years ago | G19: Nice small park in a quiet neighbourhood, one BBQ, toilet and sitting area for small gatherings. Fenced playground for your peace of mind and your little ones | H19: Everard Park Reserve | I19: 30637 | J19: 2022-10-11 | K19: {"overall_sentiment":"positive","aspects":[{"aspect":"park","category":"environment","sentiment":"positive","evidence_span":"Nice small park"},{"aspect":"neighbourhood","category":"location","sentiment":"positive","evidence_span":"quiet neighbourhood"},{"aspect":"playground","category":"safety","sentiment":"positive","evidence_span":"Fenced playground"}, {'aspect': 'sitting area',"category":'facility', 'opinion': 'for small gatherings', 'sentiment': 'neutral'}, {'aspect': 'BBQ',"category":'facility', 'opinion': 'one BBQ', 'sentiment': 'neutral'}, {'aspect': 'toilet',"category":'facility', 'opinion': 'toilet', 'sentiment': 'neutral'}]} | L19: {'sentence': 'Nice small park in a quiet neighbourhood , one BBQ , toilet and sitting area for small gatherings . Fenced playground for your peace of mind and your little ones', 'IOB': ['O', 'O', 'B-ASP', 'O', 'O', 'O', 'O', 'O', 'O', 'B-ASP', 'O', 'B-ASP', 'O', 'O', 'B-ASP', 'O', 'O', 'O', 'O', 'O', 'B-ASP', 'O', 'O', 'O', 'O', 'O', 'O', 'O', 'O', 'O'], 'tokens': ['Nice', 'small', 'park', 'in', 'a', 'quiet', 'neighbourhood', ',', 'one', 'BBQ', ',', 'toilet', 'and', 'sitting', 'area', 'for', 'small', 'gatherings', '.', 'Fenced', 'playground', 'for', 'your', 'peace', 'of', 'mind', 'and', 'your', 'little', 'ones'], 'aspect': ['park', 'BBQ', 'toilet', 'area', 'playground'], 'position': [[2], [9], [11], [14], [20]], 'sentiment': ['Positive', 'Neutral', 'Neutral', 'Neutral', 'Neutral'], 'probs': [[0.0013663839781656861, 0.0001918409689096734, 0.998441755771637], [0.0004520551301538944, 0.9741700887680054, 0.025377783924341202], [0.00041303879697807133, 0.9986251592636108, 0.0009618206531740725], [0.0006251587183214724, 0.998891294002533, 0.00048357335617765784], [0.00036160449963063, 0.9991689920425415, 0.00046939204912632704]], 'confidence': [0.9984, 0.9742, 0.9986, 0.9989, 0.9992]} | M19: 1 | N19: =LEN(K19)-LEN(SUBSTITUTE(K19,"{",""))-1 -> 6 | O19: 5 | P19: =_xlfn.XLOOKUP(B19,'g1'!B:B,'g1'!R:R) -> 6 | Q19: =_xlfn.XLOOKUP(B19,'g2'!B:B,'g2'!U:U) -> 6 | R19: =_xlfn.XLOOKUP(B19,'g3'!B:B,'g3'!R:R) -> 3 | S19: =_xlfn.XLOOKUP(D19,'g4'!D:D,'g4'!N:N) -> 6 | T19: =$N19-P19 -> 0 | U19: =$N19-Q19 -> 0 | V19: =$N19-R19 -> 3 | W19: =$N19-S19 -> 0 | X19: [{'aspect': 'park', 'opinion': 'Nice small', 'sentiment': 'positive'}, {'aspect': 'neighbourhood', 'opinion': 'quiet', 'sentiment': 'positive'}, {'aspect': 'sitting area', 'opinion': 'for small gatherings', 'sentiment': 'neutral'}, {'aspect': 'BBQ', 'opinion': 'one BBQ', 'sentiment': 'neutral'}, {'aspect': 'toilet', 'opinion': 'toilet', 'sentiment': 'neutral'}, {'aspect': 'playground', 'opinion': 'Fenced playground', 'sentiment': 'positive'}] | Y19: =FIND("[{",K19) -> 43 | Z19: =FIND("category",K19) -> 62 | AA19: =Z19-Y19-2 -> 17 | AB19: park | AD19: =FIND("[{",X19) -> 1 | AE19: =FIND("opinion",X19) -> 22 | AF19: =AE19-AD19-2 -> 19 | AG19: park | AH19: =AB19=AG19 -> TRUE
